## Promise是什么？
Promise是ES6语法规范中新增加的内置类，是用来处理JS中的异步编程的，基于Promise这个类可以对JS中复杂的异步操作进行更加优雅的处理。

### 以面向对象的思维学习Promise
Promise是ES6浏览器内置的一个类，既然是类那么这个类上面一定有自己私有的属性和方法，而且还可以通过new这个类来得到Promise类的原型上的公有的属性和方法。

Promise类上私有的属性和方法：
> Promise类在JS中属于函数，既然是函数那么一定会有length、name、caller以及argements这些每个函数都有的属性，主要还是关注以下几个类上的方法。
```js
all: ƒ all()
allSettled: ƒ allSettled()
any: ƒ any()
race: ƒ race()
reject: ƒ reject()
resolve: ƒ resolve()
```

Promise类的原型上公有的属性和方法：
> Promise类的原型上有三个方法:then,catch和finally。除此之外还有两个内置的属性：PromiseState和PromiseResult。
```js
catch: ƒ catch()
then: ƒ then()
finally: ƒ finally()
Symbol(Symbol.toStringTag): "Promise"
[[PromiseState]]: "pending"
[[PromiseResult]]: undefined
```


### Ajax的串行请求
上一个异步请求成功之后，才可以发送下一个异步请求。要实现这种串行的请求，有两种思路可以实现。

Ajax串行请求的缺点：
1. 一旦某个请求报错或者请求时间太长会导致后续所有请求都无法继续进行，阻塞页面的渲染。
2. 这种串行的多个请求只能监听请求状态为4的事件，请求状态为2的事件是无法监听的。
3. 多个请求层层嵌套，出现回调地狱的问题。

> 第一种就是基于jQuery封装好的ajax方法，将async设置为false，也就是每一个ajax请求都是同步执行的，只有上一个请求完成之后，再接着发起下一次请求。
```js
let id = null;
let score = null;
$.ajax({
	url:'api/userInfo?name=lilei',
	method:'GET',
	async:false, // 同步请求
	success:(res)=>{
		id = res.id;
	}
})

$.ajax({
	url:'api/score?scoreId=id,
	method:'GET',
	async:false,
	success:(res)=>{
		score = res.score;
	}
})
console.log('该学生的成绩为：',score);

```

> 第二种就是将async设置为true，然后在第一个ajax的success回调函数中拿到第一个请求的数据，然后接着发起第二个请求，依次类推的话，如果有很多个请求都是这样那么就会出现回调地狱的问题，代码后期维护起来很难。
```js
let id = null;
let score = null;
let rank = null;
$.ajax({
	url:'api/userInfo?name=lilei',
	method:'GET',
	async:true, // 异步请求
	success:(res)=>{
		id = res.id;
		// 拿到学生Id之后再发请求获取学生成绩
		$.ajax({
			url:'api/score?scoreId=' + id,
			method:'GET',
			async:true,
			success:(res)=>{
				score = res.score;
				// 拿到学生的成绩score之后再请求获取排名
				$.ajax({
					url:'api/ranking,
					method:'GET',
					data:{
						score,
					}
					async:true,
					success:(res)=>{
						rank = res.rank;
					}
				})
			}
		})
	}
})
```

### Ajax的并行请求
多个请求可以同时发起，等待三个请求都请求成功之后才会执行下面的事。请求的时间取决中多个请求中时间最长的那个请求。

> 问题是如果我们如何监听三个请求都已经拿到成功的结果这个时间节点呢？一般情况下还需要一个计数器count和一个callback来实现，也就是每一个请求success之后就将count加1并且执行一次callback，看当前成功的次数是否符合请求的次数。

```js
let eng = 99,
	chi = 88,
	math = 100;
let successCount = 0;

function callback(){
	if(successCount === 3){
		// 代码执行到此处，代表三个请求不同科目的成绩排名都拿到结果
		// ....执行后续的业务逻辑即可
	}
}

/* 同时发起多个请求获取成绩排名 */
$.ajax({
	url:'api/ranking?eng=' + eng,
	method:'GET',
	success:(res)=>{
		eng = res;
		successCount ++;
		callback();
	}
})

$.ajax({
	url:'api/ranking?chi=' + chi,
	method:'GET',
	success:(res)=>{
		chi = res;
		successCount ++;
		callback();
	}
})

$.ajax({
	url:'api/ranking?math=' + math,
	method:'GET',
	success:(res)=>{
		math = res;
		successCount ++;
		callback();
	}
})

```



## Promise的executor函数(执行函数)

+ 当我们想要基于new Promise来生成一个Promise类的实例的时候，Promise就会要求我们必须传入一个函数当做参数，这个函数就是executor执行函数，它是Promise类的一个回调函数，在new Promise的时候，这个传入的executor函数在Promise内部就会被执行。

> 如果不传递executor执行函数，那么new Promise()就会抛出类型错误。
```js
const promiseVm = new Promise([executor])
Uncaught TypeError: Promise resolver undefined is not a function
```

+ 在Promise内部不仅会将executor函数执行，而且会给该函数传递两个参数resolve和reject，这两个参数的类型也是函数类型。

resolve函数被执行：代表Promise处理的异步逻辑是成功的，此时会将Promise的状态修改为fullfilled
reject函数被执行：代表Promise处理的异步逻辑是失败的，此时会将Promise的状态修改为rejected

+ 而executor函数的函数体中放的就是我们需要处理的JS异步任务，任务执行成功我们执行resolve函数，任务执行失败我们执行reject函数。
注意：executor函数体中不是只能写异步任务有关的逻辑，同步的也可以，但是一般都是些异步的。
注意：任务执行的成功和失败是由自己写的业务逻辑来控制的
注意：resolve函数和reject函数我们都可以在执行的时候传递参数，这个参数会赋值给promise实例的内部属性[[PromiseValue]]


## Promise实例的三大状态
pending：初始状态，通过new Promise后的初始状态。

fullfilled：成功状态，代表在executor函数中将resolve执行了，此时告知promise当前异步任务操作的结果是成功的。

rejected：失败状态，代表在executor函数中将reject函数执行了，此时告知promise当前异步任务操作的结果是失败的。

> example
```js
const promiseVm = new Promise((resolve,reject)=>{
	setTimeout(()=>{
		if(Math.random() >= 0.5){
			reject('小于0.5,任务失败')
		}else{
			resolve('大于等于0.5,任务成功')
		}
	},1000)
})
```

> 上述代码的执行顺序和promise实例内部变化的过程为：

1. 首先当我们new Promise并传入一个executor函数之后，此时会生成一个Promise类的实例promiseVm。然后Promise类内部会将传入的executor函数立即执行，执行executor函数的过程也就是执行函数体内异步代码的过程，此时该实例promiseVm的内部状态为等待状态:
[[PromiseStatus]]:pending;
[[PromiseValue]]:undefined;

2. 等待异步任务执行完毕(比如定时器异步任务在1000ms之后执行完毕),此时根据我们写在异步代码中的业务逻辑来决定执行resolve还是reject函数。

3. 如果执行了resolve函数，那么代表异步任务的处理结果为成功，此时promiseVm实例的内部状态修改为成功：
[[PromiseStatus]]:fullfilled;
[[PromiseValue]]:'大于等于0.5,任务成功';

4. 如果执行了reject函数，那么代表异步任务的处理结果为失败，此时promiseVm实例的内部状态修改为失败：
[[PromiseStatus]]:rejected;
[[PromiseValue]]:'小于0.5,任务失败';

## Promise的实例上的then\catch\finally方法

1. 一旦Promise内部的resolve或者reject函数被执行的时候，promise实例内部的状态就会立即会从pending修改为fullfilled或者rejected,不会存在先执行resolve后执行reject函数，状态先变为fullfilled然后又变为rejected的这种情况。也就是promise内部的状态是不可逆的。

2. 一旦promise实例的内部状态发生改变的时候，就会通知事件池中的方法执行，也就是then方法传入的回调函数会被执行。then方法定义了promise成功或者失败后需要依次执行的业务逻辑。

Promise.prototype.then方法：设置promise状态为成功或者失败后执行的回调函数
 promise.then(success,error) 成功和失败都设置
 promise.then(success)       只设置成功
 promise.then(null,error)   只设置失败

Promise.prototype.catch方法：设置promise状态为失败后执行的回调函数
 promise.catch(err=>{})
 
Promise.prototype.finally方法：无论状态为成功或者失败都会被执行的回调函数
 promise.finally(msg=>{})
 
> try catch finally是基于js中异常捕获来实现的
```js
try{
	// 有可能存在错误的代码
}catch(err){
	// try中出现错误的时候执行，err是错误对象
}finally(){
	// 不管错误或者正确，这里的代码都会执行
}

```


```js

const promiseVm = new Promise((resolve,reject)=>{
	setTimeout(()=>{
		if(Math.random() >= 0.5){
			reject('小于0.5,任务失败')
		}else{
			resolve('大于等于0.5,任务成功')
		}
	},1000)
})

promise.then(res=>{
	// 状态变为fullfilled之后执行的回调函数，res就是resolve函数执行时传入的实参
},err=>{
	// 状态变为rejected之后执行的回调函数，err就是reject函数执行时传入的实参
})
```

## promise.then的链式调用
promise.then()方法执行的结果:将then方法接受的参数也就是回调函数依次放入事件池中,所以then方法的参数也可以看作:promise.then(onResolve,onReject)，也就是监听promise内部状态变化为成功或者失败的事件侦听器

事件池中的回调函数执行的时机:当监听到promise内部的状态发生改变的时候,原先放入事件池中的回调函数会执行。

执行then\catch\finally返回的结果是一个全新的Promise实例
```js
new Promise((resolve,reject)=>{
	setTimeout(()=>{
		let num = Math.random();
		num >= 0.5?resolve('大于等于0.5,任务成功'):reject('小于0.5,任务失败');
	},1000)
})
```

then链式调用的基础：每一个promise实例执行then方法都会返回一个新的promise实例，只要是promise实例它上面就会有then\catch和finally方法可被调用，所以可被链式调用。

下一个promise实例上then方法执行成功的还是失败的回调函数，取决于上一个promise实例上then方法中的回调函数执行是否出错，如果没有出错，那么无论上一个执行的是成功回调还是失败回调，下一个promise中的then方法都会执行成功的回调；如果一旦报错，那么一定会执行下一个promise中的then方法的失败回调。不要以为上一个执行的是err回调，链式调用的时候下一个也会自动去执行err回调。

上一个promise实例上then方法中的某一个回调函数的return返回值，会当作参数传递给下一个promise实例上then方法中的回调函数的形参。

```js
let promise1 = new Promise((resolve,reject)=>{
		setTimeout(()=>{
			resolve(100);
			reject(-100);
		},1000)
	}).then(res=>{
		console.log('promise1状态成功:' + res);
		return res *10;
	},err=>{
		console.log('promise1状态失败:' + err);
		return err / 10;
	}).then(res=>{
		console.log('promise2状态成功:' + res);
	},err=>{
		console.log('promise2状态失败:' + err.message);
	})

resolve(100):promise1内部状态修改为fullfilled,执行第一个then方法中的成功回调，100会传递给参数res,打印:promise1状态成功:100

return res *10:将下一个链式调用的promise实例的PromiseValue修改为100 * 10 = 1000；此时会执行下一个then方法中的成功回调，打印：promise2状态成功:1000

如果是reject(100)的话会先执行第一个then的err回调，并且return出去一个-100 / 10 = -10；此时并不会进入到下一个then的err回调中去，以为上一个then方法的回调执行并没有报错，所以还是会进入到下一个then方法中的成功回调，打印：promise2状态成功：-10
```

上一个then方法中的两个回调的其中一个执行的时候是否报错？
	是 --- 进入到下一个then方法的失败回调中，并将报错对象被err参数接受
	否？
		是否return了值？
			是 --- 进入到下一个then方法的成功回调中，并将return的值被res接受
			否 --- 进入到下一个then方法的成功回调中，并将undefiend的值传递给res接受
			

如果当前promise实例的状态确定后，都会到该实例上的then方法中找失败或者成功的回调函数执行，如果有些时候then方法只监听了成功回调，没有失败回调，那么此时就会向下顺延。

```js
如果promise实例的then方法中只有成功的回调而没有失败的回调，那么此时如果resolve函数被执行，则执行then方法中的成功回调；如果reject函数被执行，则执行then方法中的失败回调，但是then方法中并没有监听错误回调，此时就会沿着then链向下查找：
	如果下一个promise实例有then方法，那么执行then方法中的失败回调
	如果下一个promise实例有catch方法，那么将catch方法中的失败回调执行
这就是我们日常开发中连着写then和catch的由来。
 new Promise((resolve,reject)=>{
		setTimeout(()=>{
			resolve(100);
		},1000)
	}).then(res=>{
		console.log('promise1状态成功:' + res);
		return res *10;
	}).catch(err=>{
		console.log('promise1状态失败:' + err);
	})
```

如果then方法只有一个且在成功回调中执行时代码报错，那么就会执行下一个promise实例中的catch方法，并且报错的错误对象会被catch方法中的err参数所接受。
```js 
 new Promise((resolve,reject)=>{
		setTimeout(()=>{
			resolve(100);
		},1000)
	}).then(res=>{
		console.log('promise1状态成功:' + a); // 没有a变量，此时代码报错，promise状态变为失败
		return res *10;
	}).catch(err=>{
		// 在这里捕获到上一个promise中的错误对象
		console.log('promise1状态失败:' + err.message);
	})
```

.then.catch的写法，有两种情况会执行catch中的回调：
1. executor中执行的reject函数，将promise的状态修改为rejected，此时先执行then方法中的onRejected，如果有就将其执行;如果没有就沿着链执行下一个promise中的catch方法的失败回调，此时catch的err参数接收的是executor中reject函数执行时传递的实参。
2. exxcutor执行了resolve函数，将promise的状态修改为fullfileld，此时先执行then方法中的onResolved成功回调，如果在执行该函数的过程中有js的报错，那么此时这一个promise的状态就变为rejected，此时就会沿着链执行下一个promise的catch方法的失败回调，此时catch的err参数接收的是上一个promise的then方法的成功回调中js报错的错误对象。

then里面写两个方法和.then... .catch链式写的好处：
```js
只能捕获第一个proimis中也就是executor中promise状态变为rejected要执行的失败信息，如果状态变为fullfilled之后执行then方法中的成功回调在执行的时候报错了，那么这个错误是没法捕获的。
new Promise((resolve,reject)=>{
	reject('失败');
}).then(res=>{
	console.log(res);
},err=>{
	console.log(err);
})

不仅可以捕获第一个promise也就是executor中promise状态变为rejected要执行的失败信息,而且可以捕获上一个promise的then方法在执行时的报错。
new Promise((resolve,reject)=>{
	reject('失败');
}).then(res=>{
	console.log(a); //报错，后续代码不再执行，会将错误对象传递出去
	return 100; 
}).catch(err=>{
	console.log(err); // 捕获到上一个then方法执行时的报错
})
```

then和catch监听的回调执行与否都取决于上一个promise实例执行是否报错。

```js
new Promise((resolve,reject)=>{
	resolve('成功');
}).then(res=>{
	console.log(a); // 报错
}).catch(err=>{
	console.log(err); // 捕获错误
}).then(res=>{
	// 上一个promise实例的catch方法执行并没有报错，所以这里的方法也会执行
})
```

1.如果then或者catch方法中任何回调都没有监听,那么会直接跳过执行一个promise实例的方法
2.如果then方法的成功回调函数中console.log(a)这行代码执行出错，那么控制台不会打印任何信息的,只有catch进行捕获之后才会打印到此错误信息。
3.如果then方法写了分别监听成功和失败的回调，那么上一个promise的错误也是可以捕获的
```js
new Promise((resolve,reject)=>{
		resolve();
	}).then().catch(err=>{
		console.log(1);
	}).then(res=>{
		console.log(2)  // => 输出2
	}).then(res=>{
		console.log(3)  // => 输出3
	}).catch(res=>{
		console.log(4)
	}).then(res=>{
		console.log(a) // => 代码报错，promise状态改变，不会打印任何东西
	}).catch().then(null,err=>{
		console.log(5); // => 执行then方法的第二个错误回调，输出5
	})
```


## 基于Promise解决Ajax请求的串行和并行存在的一些问题 

### 1. 解决ajax串行请求导致的回调地狱
```js
let id = null;
let score = null;
let rank = null;
$.ajax({
	url:'api/userInfo?name=lilei',
	method:'GET',
	async:true, // 异步请求
	success:(res)=>{
		id = res.id;
		// 拿到学生Id之后再发请求获取学生成绩
		$.ajax({
			url:'api/score?scoreId=' + id,
			method:'GET',
			async:true,
			success:(res)=>{
				score = res.score;
				// 拿到学生的成绩score之后再请求获取排名
				$.ajax({
					url:'api/ranking,
					method:'GET',
					data:{
						score,
					}
					async:true,
					success:(res)=>{
						rank = res.rank;
					}
				})
			}
		})
	}
})

```


解决Ajax串行导致回调地狱问题的内置原理:
Promise的链式写法解决回调地狱:
1. 需要将每一个异步任务都用一个对应的函数将异步代码用Promise的executor包装起来，然后return出去
2. THEN方法中如果return的是一个Promise实例，那么当前返回的这个Promise实例内部的成功或者失败状态，会影响下一个Then方法中是执行成功回调还是失败回调
3. THEN方法中如果return的是一个普通的JS值或者不return也就是默认return undefined，那么下一个promise实例的then方法是执行成功回调还是错误回调取决于代码执行是否报错

```js
/* 请求获取学生ID的方法 */
function getUserId(){
	return new Promise((resolve,reject)=>{
		setTimeout(()=>{
			let userInfo = {
				id:'0001',
				name:'lilei'
			}
			resolve(userInfo);
		},1000)
	})
}

/* 请求获取学生成绩的方法 */
function getUserScore(){
	return new Promise((resolve,reject)=>{
		setTimeout(()=>{
			let scoreInfo = {
				chinese:'100分',
				math:'99分'
			}
			resolve(scoreInfo);
		},1000)
	})
}

/* 请求获取学生成绩排名的方法 */
function getUserRank(score){
	return new Promise((resolve,reject)=>{
		setTimeout(()=>{
			let rank = '第1名';
			resolve(rank);
		},1000)
	})
}

getUserId().then(userInfo=>{
	console.log('学生的ID为:',userInfo.id);
	let id = userInfo.id;
	return getUserScore(id);
}).then(scoreInfo=>{
	console.log('语文的分数为:',scoreInfo.chinese);
	let score = scoreInfo.chinese;
	return getUserRank(score);
}).then(rank=>{
	console.log('语文成绩的排名为:',rank);
})

/* ES6简写更加简单*/
getUserId()
	.then(userInfo=>getUserScore(userInfo.id))
	.then(scoreInfo=>getUserRank(scoreInfo.chinese))
	.then(rank=>{
	console.log('语文成绩的排名为:',rank);
  })
  
/* ES7 async和await 代码看着请求是同一时间发起，其实是串行的 */
async function func(){
	let userInfo = await getUserId();
	let scoreInfo = await getUserScore(userInfo.id);
	let rank = await getUserRank(scoreInfo.chinese);
	console.log('语文成绩的排名为:',rank);
}
func();
```

### 2. 解决ajax并行请求的等待问题和计数器
需求：同时发起三个请求，必须要等到三个请求都返回结果之后才可以进行下一步操作。
解决方案: Promise.all([promise1,promise2,...])
Promise.all()方法接收一个数组作为参数，数组可以传入一到多个promise实例,该方法的返回值也是一个promsie实例。
当所有promise实例的状态都变为fullfilled的时候，此时Promise.all()方法返回的这个实例的内部状态也会被修改为fullfilled，此时执行then方法中的成功回调，then方法中的成功回调函数的参数也是一个数组，依次顺序接收了多个promsie实例返回的成功的结果；而如果有一个失败，那么就会执行then方法的失败回调或者catch方法。


Promise.race()方法接收一个数组作为参数，数组可以传入一到多个promise实例,该方法的返回值也是一个promsie实例。
当所有promise实例中的某一个实例的状态最先发生变化的时候，这种变化可能是失败也可能是成功。此时Promise.race()方法返回的这个实例的内部状态也会被对应修改为fullfilled或者rejected，然后会分别执行对应的then方法或者catch方法的回调函数.


```js
/* 请求获取语文成绩的排名 */
function getRank1(){
	return new Promise((resolve,reject)=>{
		setTimeout(()=>{
			resolve('语文成绩是第1名');
		},1000)
	})
}

/* 请求获取数学成绩的排名 */
function getRank2(){
	return new Promise((resolve,reject)=>{
		setTimeout(()=>{
			resolve('数学成绩是第2名');
		},500)
	})
}

/* 请求获取英语成绩的排名 */
function getRank3(){
	return new Promise((resolve,reject)=>{
		setTimeout(()=>{
			resolve('英语成绩是第3名');
		},3000)
	})
}

Promise.all([getRank1(),getRank2(),getRank3()]).then(results=>{
	const [rank1,rank2,rank3] = results;
	console.log(rank1);
	console.log(rank2);
	console.log(rank3);
}).catch(err=>{
	console.log(err);
})

Promise.race([getRank1(),getRank2(),getRank3()]).then(result=>{
	const fastRank = result;
	console.log('最快获取到的信息是:',fastRank);
})

```


## ES7新增语法糖 async await

+ 函数中只要使用await，该函数必须用async修饰符进行修饰；但是async修饰符是可以单独使用的,单独使用async修饰符修饰一个函数之后，如果函数内部没有await，那么会控制函数内部return的值是一个Promise实例，比如：
如果是以下几种情况那么默认会将函数的返回值包装为一个Promise类的实例，并且把这个实例的状态修改为fulfilled；实例的修改为return出去的值。
 1. return一个非Promise类的实例
 2. return了一个本来就是Promise类的实例
 3. 函数默认不返回任何内容，等于return undefined
 ```js
 async function demo(){
 	return 100;
	return Promise.resolve(88);
	// return undefined;
 }
 console.log(demo());
 
 [[PromiseState]]: "fulfilled"
 [[PromiseResult]]: 100 / 88 / undeinfed
 ```
如果是以下几种情况那么会返回一个状态为rejected，值为错误对象的Promise实例。
 1. 函数执行过程中报错
 2. 手动throw了一个Error对象
```js
async function demo(){
	throw new TypeError('类型错误')
}
async function demo(){
	console.log(a);
}

console.log(demo());

/* then的第二个onRejected捕获错误 */
demo().then(res=>{
	console.log(res);
},err=>{
	console.log(err.message);
})

/* 用catch方法直接捕获错误 */
demo().catch(err=>{
	console.log(err.message);
})

[[PromiseState]]: "rejected"
[[PromiseResult]]: TypeError: 类型错误
```

+ await可以理解为用于等待一个Promise对象或者任何药等待的值：
如果等待的是Promsie实例，那么会暂停当前async函数的执行，等待Promise内部状态发生改变，如果处理结果为成功那么resolve函数参数就是await表达式的值；如果处理结果为失败那么await会将Promise的异常原因抛出。

如果等待的是一个普通的JavaScript值，那么返回其值本身。

+ async - await 捕获异常的问题

> 如果异常是同步抛出的，trycatch可以捕获
```js
async function init() {
	try {
		const userScore = await new Promise((resolve, reject) => {
			let userScore;
			throw new Error('1896');  
		});

	} catch (e) {
		console.log(e); // Error: 1896
	}
}
init();

```

> 如果异常在异步代码中抛出，那么try catch不可以捕获

```js
async function init() {
	try {
		const userScore = await new Promise((resolve, reject) => {
			let userScore;
			setTimeout(() => {
				userScore = 100;
				throw new Error('1896');
			}, 1500)
			
		});

	} catch (e) {
		console.log(e); // 并不能捕获到异常
	}
}
init();

```